]11;?\]10;?\
   FastAPI   Starting production server üöÄ
 
             Searching for package file structure from directories with __init__.py files
             Importing from /data/code/ScienceBoard/env_server
 
    module   üêç env_server_launch.py
 
      code   Importing the FastAPI app object from the module with the following code:
 
             from env_server_launch import app
 
       app   Using import string: env_server_launch:app
 
    server   Server started at http://0.0.0.0:10014
    server   Documentation at http://0.0.0.0:10014/docs
 
             Logs:
 
]11;?\]10;?\]11;?\]10;?\      INFO   Started server process [103271]
      INFO   Waiting for application startup.
      INFO   Application startup complete.
      INFO   Uvicorn running on http://0.0.0.0:10014 (Press CTRL+C to quit)
      INFO   127.0.0.1:47740 - "GET / HTTP/1.1" 200
[2025-07-03 11:15:26] [env api] vitual machine starting...
Starting VMware VM...
[2025-07-03 11:15:27] [env api] vitual machine done.
      INFO   127.0.0.1:47744 - "POST /start HTTP/1.1" 200
      INFO   127.0.0.1:47750 - "POST /get_task_config HTTP/1.1" 200
[2025-07-03 11:15:29] [env api] env reset starting...
Starting VMware VM...
execute payload /bin/bash /home/user/server/reset.sh True
base url http://192.168.23.129:5000/setup/execute
request payload {'json': {'command': '/bin/bash /home/user/server/reset.sh', 'shell': True}, 'headers': {'Content-Type': 'application/json'}}
API server reset response: True
base url http://192.168.23.129:5000/opt
request payload {'json': {'depth': 6}, 'headers': {'Content-Type': 'application/json'}}
execute payload LD_LIBRARY_PATH=/home/user/6.5.0/gcc_64/lib /app/bin/celestia-qt6 8000 True
base url http://192.168.23.129:5000/setup/launch
request payload {'json': {'command': 'LD_LIBRARY_PATH=/home/user/6.5.0/gcc_64/lib /app/bin/celestia-qt6 8000', 'shell': True}, 'headers': {'Content-Type': 'application/json'}}
logging succeed True
[2025-07-03 11:15:49] [env api] env reset done...
      INFO   127.0.0.1:47760 - "POST /reset HTTP/1.1" 200
Traceback (most recent call last):
  File "/home/PJLAB/wangxuehui/miniconda3/envs/sci/lib/python3.11/site-packages/urllib3/connection.py", line 198, in _new_conn
    sock = connection.create_connection(
           ^^^^^^^^^^^^^^^^^^^^^^^^^^^^^
  File "/home/PJLAB/wangxuehui/miniconda3/envs/sci/lib/python3.11/site-packages/urllib3/util/connection.py", line 85, in create_connection
    raise err
  File "/home/PJLAB/wangxuehui/miniconda3/envs/sci/lib/python3.11/site-packages/urllib3/util/connection.py", line 73, in create_connection
    sock.connect(sa)
ConnectionRefusedError: [Errno 111] Connection refused

The above exception was the direct cause of the following exception:

Traceback (most recent call last):
  File "/home/PJLAB/wangxuehui/miniconda3/envs/sci/lib/python3.11/site-packages/urllib3/connectionpool.py", line 787, in urlopen
    response = self._make_request(
               ^^^^^^^^^^^^^^^^^^^
  File "/home/PJLAB/wangxuehui/miniconda3/envs/sci/lib/python3.11/site-packages/urllib3/connectionpool.py", line 493, in _make_request
    conn.request(
  File "/home/PJLAB/wangxuehui/miniconda3/envs/sci/lib/python3.11/site-packages/urllib3/connection.py", line 445, in request
    self.endheaders()
  File "/home/PJLAB/wangxuehui/miniconda3/envs/sci/lib/python3.11/http/client.py", line 1298, in endheaders
    self._send_output(message_body, encode_chunked=encode_chunked)
  File "/home/PJLAB/wangxuehui/miniconda3/envs/sci/lib/python3.11/http/client.py", line 1058, in _send_output
    self.send(msg)
  File "/home/PJLAB/wangxuehui/miniconda3/envs/sci/lib/python3.11/http/client.py", line 996, in send
    self.connect()
  File "/home/PJLAB/wangxuehui/miniconda3/envs/sci/lib/python3.11/site-packages/urllib3/connection.py", line 276, in connect
    self.sock = self._new_conn()
                ^^^^^^^^^^^^^^^^
  File "/home/PJLAB/wangxuehui/miniconda3/envs/sci/lib/python3.11/site-packages/urllib3/connection.py", line 213, in _new_conn
    raise NewConnectionError(
urllib3.exceptions.NewConnectionError: <urllib3.connection.HTTPConnection object at 0x7ff0206de390>: Failed to establish a new connection: [Errno 111] Connection refused

The above exception was the direct cause of the following exception:

Traceback (most recent call last):
  File "/home/PJLAB/wangxuehui/miniconda3/envs/sci/lib/python3.11/site-packages/requests/adapters.py", line 486, in send
    resp = conn.urlopen(
           ^^^^^^^^^^^^^
  File "/home/PJLAB/wangxuehui/miniconda3/envs/sci/lib/python3.11/site-packages/urllib3/connectionpool.py", line 841, in urlopen
    retries = retries.increment(
              ^^^^^^^^^^^^^^^^^^
  File "/home/PJLAB/wangxuehui/miniconda3/envs/sci/lib/python3.11/site-packages/urllib3/util/retry.py", line 519, in increment
    raise MaxRetryError(_pool, url, reason) from reason  # type: ignore[arg-type]
    ^^^^^^^^^^^^^^^^^^^^^^^^^^^^^^^^^^^^^^^^^^^^^^^^^^^
urllib3.exceptions.MaxRetryError: HTTPConnectionPool(host='192.168.23.129', port=8000): Max retries exceeded with url: /dump (Caused by NewConnectionError('<urllib3.connection.HTTPConnection object at 0x7ff0206de390>: Failed to establish a new connection: [Errno 111] Connection refused'))

During handling of the above exception, another exception occurred:

Traceback (most recent call last):
  File "/data/code/ScienceBoard/env_server/env_server_launch.py", line 119, in evaluate
    metric = manager.evaluate()
             ^^^^^^^^^^^^^^^^^^
  File "/data/code/ScienceBoard/env_server/manager/base.py", line 140, in evaluate
    result = self.metric.eval()
             ^^^^^^^^^^^^^^^^^^
  File "/data/code/ScienceBoard/env_server/eval/Celestia/eval.py", line 15, in eval
    info = self.manager.status_dump(self.query)
           ^^^^^^^^^^^^^^^^^^^^^^^^^^^^^^^^^^^^
  File "/data/code/ScienceBoard/env_server/manager/Celestia/manager.py", line 29, in status_dump
    return self._post("/dump", data=json.dumps(query)).json()
           ^^^^^^^^^^^^^^^^^^^^^^^^^^^^^^^^^^^^^^^^^^^
  File "/data/code/ScienceBoard/env_server/manager/Celestia/manager.py", line 19, in <lambda>
    self._post = lambda path, **kwargs: requests.post(
                                        ^^^^^^^^^^^^^^
  File "/home/PJLAB/wangxuehui/miniconda3/envs/sci/lib/python3.11/site-packages/requests/api.py", line 115, in post
    return request("post", url, data=data, json=json, **kwargs)
           ^^^^^^^^^^^^^^^^^^^^^^^^^^^^^^^^^^^^^^^^^^^^^^^^^^^^
  File "/home/PJLAB/wangxuehui/miniconda3/envs/sci/lib/python3.11/site-packages/requests/api.py", line 59, in request
    return session.request(method=method, url=url, **kwargs)
           ^^^^^^^^^^^^^^^^^^^^^^^^^^^^^^^^^^^^^^^^^^^^^^^^^
  File "/home/PJLAB/wangxuehui/miniconda3/envs/sci/lib/python3.11/site-packages/requests/sessions.py", line 589, in request
    resp = self.send(prep, **send_kwargs)
           ^^^^^^^^^^^^^^^^^^^^^^^^^^^^^^
  File "/home/PJLAB/wangxuehui/miniconda3/envs/sci/lib/python3.11/site-packages/requests/sessions.py", line 703, in send
    r = adapter.send(request, **kwargs)
        ^^^^^^^^^^^^^^^^^^^^^^^^^^^^^^^
  File "/home/PJLAB/wangxuehui/miniconda3/envs/sci/lib/python3.11/site-packages/requests/adapters.py", line 519, in send
    raise ConnectionError(e, request=request)
requests.exceptions.ConnectionError: HTTPConnectionPool(host='192.168.23.129', port=8000): Max retries exceeded with url: /dump (Caused by NewConnectionError('<urllib3.connection.HTTPConnection object at 0x7ff0206de390>: Failed to establish a new connection: [Errno 111] Connection refused'))
[2025-07-03 11:15:50] [env api] evaluate failed: HTTPConnectionPool(host='192.168.23.129', port=8000): Max retries exceeded with url: /dump (Caused by NewConnectionError('<urllib3.connection.HTTPConnection object at 0x7ff0206de390>: Failed to establish a new connection: [Errno 111] Connection refused'))
      INFO   127.0.0.1:52704 - "GET /evaluate HTTP/1.1" 200
